2021-05-26 14:08:39,691 ERROR: Exception on /search [GET] [in D:\Programs\Anaconda\envs\watchmovie\lib\site-packages\flask\app.py:1454]
Traceback (most recent call last):
  File "D:\Programs\Anaconda\envs\watchmovie\lib\site-packages\flask\app.py", line 2070, in wsgi_app
    response = self.full_dispatch_request()
  File "D:\Programs\Anaconda\envs\watchmovie\lib\site-packages\flask\app.py", line 1515, in full_dispatch_request
    rv = self.handle_user_exception(e)
  File "D:\Programs\Anaconda\envs\watchmovie\lib\site-packages\flask\app.py", line 1513, in full_dispatch_request
    rv = self.dispatch_request()
  File "D:\Programs\Anaconda\envs\watchmovie\lib\site-packages\flask\app.py", line 1499, in dispatch_request
    return self.ensure_sync(self.view_functions[rule.endpoint])(**req.view_args)
  File "D:\Programs\Anaconda\envs\watchmovie\lib\site-packages\flask_login\utils.py", line 272, in decorated_view
    return func(*args, **kwargs)
  File "C:\Users\Vivo\Desktop\heroku-app\watchmovie\src\main\routes.py", line 47, in search
    suggestions = get_suggestions()
  File "C:\Users\Vivo\Desktop\heroku-app\watchmovie\ml\trained_model.py", line 59, in get_suggestions
    data = pd.read_csv('src/ml/main_data.csv')
  File "D:\Programs\Anaconda\envs\watchmovie\lib\site-packages\pandas\io\parsers.py", line 610, in read_csv
    return _read(filepath_or_buffer, kwds)
  File "D:\Programs\Anaconda\envs\watchmovie\lib\site-packages\pandas\io\parsers.py", line 462, in _read
    parser = TextFileReader(filepath_or_buffer, **kwds)
  File "D:\Programs\Anaconda\envs\watchmovie\lib\site-packages\pandas\io\parsers.py", line 819, in __init__
    self._engine = self._make_engine(self.engine)
  File "D:\Programs\Anaconda\envs\watchmovie\lib\site-packages\pandas\io\parsers.py", line 1050, in _make_engine
    return mapping[engine](self.f, **self.options)  # type: ignore[call-arg]
  File "D:\Programs\Anaconda\envs\watchmovie\lib\site-packages\pandas\io\parsers.py", line 1867, in __init__
    self._open_handles(src, kwds)
  File "D:\Programs\Anaconda\envs\watchmovie\lib\site-packages\pandas\io\parsers.py", line 1362, in _open_handles
    self.handles = get_handle(
  File "D:\Programs\Anaconda\envs\watchmovie\lib\site-packages\pandas\io\common.py", line 642, in get_handle
    handle = open(
FileNotFoundError: [Errno 2] No such file or directory: 'src/ml/main_data.csv'
2021-05-26 14:08:44,211 ERROR: Exception on /random/result [GET] [in D:\Programs\Anaconda\envs\watchmovie\lib\site-packages\flask\app.py:1454]
Traceback (most recent call last):
  File "D:\Programs\Anaconda\envs\watchmovie\lib\site-packages\flask\app.py", line 2070, in wsgi_app
    response = self.full_dispatch_request()
  File "D:\Programs\Anaconda\envs\watchmovie\lib\site-packages\flask\app.py", line 1515, in full_dispatch_request
    rv = self.handle_user_exception(e)
  File "D:\Programs\Anaconda\envs\watchmovie\lib\site-packages\flask\app.py", line 1513, in full_dispatch_request
    rv = self.dispatch_request()
  File "D:\Programs\Anaconda\envs\watchmovie\lib\site-packages\flask\app.py", line 1499, in dispatch_request
    return self.ensure_sync(self.view_functions[rule.endpoint])(**req.view_args)
  File "C:\Users\Vivo\Desktop\heroku-app\watchmovie\src\main\routes.py", line 72, in result
    return render_template('result.html', title=title, overview=overview, poster=poster,
UnboundLocalError: local variable 'overview' referenced before assignment
2021-05-26 14:09:52,329 INFO: Watchmovie startup [in C:\Users\Vivo\Desktop\heroku-app\watchmovie\src\__init__.py:74]
2021-05-26 14:09:52,502 ERROR: Exception on /random/result [GET] [in D:\Programs\Anaconda\envs\watchmovie\lib\site-packages\flask\app.py:1454]
Traceback (most recent call last):
  File "D:\Programs\Anaconda\envs\watchmovie\lib\site-packages\flask\app.py", line 2070, in wsgi_app
    response = self.full_dispatch_request()
  File "D:\Programs\Anaconda\envs\watchmovie\lib\site-packages\flask\app.py", line 1515, in full_dispatch_request
    rv = self.handle_user_exception(e)
  File "D:\Programs\Anaconda\envs\watchmovie\lib\site-packages\flask\app.py", line 1513, in full_dispatch_request
    rv = self.dispatch_request()
  File "D:\Programs\Anaconda\envs\watchmovie\lib\site-packages\flask\app.py", line 1499, in dispatch_request
    return self.ensure_sync(self.view_functions[rule.endpoint])(**req.view_args)
  File "C:\Users\Vivo\Desktop\heroku-app\watchmovie\src\main\routes.py", line 72, in result
    return render_template('result.html', title=title, overview=overview, poster=poster,
UnboundLocalError: local variable 'overview' referenced before assignment
2021-05-26 14:09:55,135 ERROR: Exception on /random/result [GET] [in D:\Programs\Anaconda\envs\watchmovie\lib\site-packages\flask\app.py:1454]
Traceback (most recent call last):
  File "D:\Programs\Anaconda\envs\watchmovie\lib\site-packages\flask\app.py", line 2070, in wsgi_app
    response = self.full_dispatch_request()
  File "D:\Programs\Anaconda\envs\watchmovie\lib\site-packages\flask\app.py", line 1515, in full_dispatch_request
    rv = self.handle_user_exception(e)
  File "D:\Programs\Anaconda\envs\watchmovie\lib\site-packages\flask\app.py", line 1513, in full_dispatch_request
    rv = self.dispatch_request()
  File "D:\Programs\Anaconda\envs\watchmovie\lib\site-packages\flask\app.py", line 1499, in dispatch_request
    return self.ensure_sync(self.view_functions[rule.endpoint])(**req.view_args)
  File "C:\Users\Vivo\Desktop\heroku-app\watchmovie\src\main\routes.py", line 72, in result
    return render_template('result.html', title=title, overview=overview, poster=poster,
UnboundLocalError: local variable 'overview' referenced before assignment
2021-05-26 14:11:07,902 ERROR: Exception on /random/result [GET] [in D:\Programs\Anaconda\envs\watchmovie\lib\site-packages\flask\app.py:1454]
Traceback (most recent call last):
  File "D:\Programs\Anaconda\envs\watchmovie\lib\site-packages\flask\app.py", line 2070, in wsgi_app
    response = self.full_dispatch_request()
  File "D:\Programs\Anaconda\envs\watchmovie\lib\site-packages\flask\app.py", line 1515, in full_dispatch_request
    rv = self.handle_user_exception(e)
  File "D:\Programs\Anaconda\envs\watchmovie\lib\site-packages\flask\app.py", line 1513, in full_dispatch_request
    rv = self.dispatch_request()
  File "D:\Programs\Anaconda\envs\watchmovie\lib\site-packages\flask\app.py", line 1499, in dispatch_request
    return self.ensure_sync(self.view_functions[rule.endpoint])(**req.view_args)
  File "C:\Users\Vivo\Desktop\heroku-app\watchmovie\src\main\routes.py", line 72, in result
    return render_template('result.html', title=title, overview=overview, poster=poster,
UnboundLocalError: local variable 'overview' referenced before assignment
2021-05-26 14:11:31,078 ERROR: Exception on /random/result [GET] [in D:\Programs\Anaconda\envs\watchmovie\lib\site-packages\flask\app.py:1454]
Traceback (most recent call last):
  File "D:\Programs\Anaconda\envs\watchmovie\lib\site-packages\flask\app.py", line 2070, in wsgi_app
    response = self.full_dispatch_request()
  File "D:\Programs\Anaconda\envs\watchmovie\lib\site-packages\flask\app.py", line 1515, in full_dispatch_request
    rv = self.handle_user_exception(e)
  File "D:\Programs\Anaconda\envs\watchmovie\lib\site-packages\flask\app.py", line 1513, in full_dispatch_request
    rv = self.dispatch_request()
  File "D:\Programs\Anaconda\envs\watchmovie\lib\site-packages\flask\app.py", line 1499, in dispatch_request
    return self.ensure_sync(self.view_functions[rule.endpoint])(**req.view_args)
  File "C:\Users\Vivo\Desktop\heroku-app\watchmovie\src\main\routes.py", line 72, in result
    return render_template('result.html', title=title, overview=overview, poster=poster,
UnboundLocalError: local variable 'overview' referenced before assignment
2021-05-26 14:12:18,781 ERROR: Exception on /random/result [GET] [in D:\Programs\Anaconda\envs\watchmovie\lib\site-packages\flask\app.py:1454]
Traceback (most recent call last):
  File "D:\Programs\Anaconda\envs\watchmovie\lib\site-packages\flask\app.py", line 2070, in wsgi_app
    response = self.full_dispatch_request()
  File "D:\Programs\Anaconda\envs\watchmovie\lib\site-packages\flask\app.py", line 1515, in full_dispatch_request
    rv = self.handle_user_exception(e)
  File "D:\Programs\Anaconda\envs\watchmovie\lib\site-packages\flask\app.py", line 1513, in full_dispatch_request
    rv = self.dispatch_request()
  File "D:\Programs\Anaconda\envs\watchmovie\lib\site-packages\flask\app.py", line 1499, in dispatch_request
    return self.ensure_sync(self.view_functions[rule.endpoint])(**req.view_args)
  File "C:\Users\Vivo\Desktop\heroku-app\watchmovie\src\main\routes.py", line 72, in result
    return render_template('result.html', title=title, overview=overview, poster=poster,
UnboundLocalError: local variable 'overview' referenced before assignment
2021-05-26 14:13:21,518 ERROR: Exception on /random/result [GET] [in D:\Programs\Anaconda\envs\watchmovie\lib\site-packages\flask\app.py:1454]
Traceback (most recent call last):
  File "D:\Programs\Anaconda\envs\watchmovie\lib\site-packages\flask\app.py", line 2070, in wsgi_app
    response = self.full_dispatch_request()
  File "D:\Programs\Anaconda\envs\watchmovie\lib\site-packages\flask\app.py", line 1515, in full_dispatch_request
    rv = self.handle_user_exception(e)
  File "D:\Programs\Anaconda\envs\watchmovie\lib\site-packages\flask\app.py", line 1513, in full_dispatch_request
    rv = self.dispatch_request()
  File "D:\Programs\Anaconda\envs\watchmovie\lib\site-packages\flask\app.py", line 1499, in dispatch_request
    return self.ensure_sync(self.view_functions[rule.endpoint])(**req.view_args)
  File "C:\Users\Vivo\Desktop\heroku-app\watchmovie\src\main\routes.py", line 72, in result
    return render_template('result.html', title=title, overview=overview, poster=poster,
UnboundLocalError: local variable 'overview' referenced before assignment
